Workbook
Name aapl_us_d: Data!$A$1:$B$1256

Sheet Data
A1: Date | B1: Daily Closing Price | C1: Return | D1: Rolling Std. dev.(250 days) | E1: Rolling VaR %(95%) | F1: Rolling VaR %(99%) | G1: Negative rolling VaR(95%) | H1: Negative rolling VaR(99%)
A2: 44407 | B2: 142.309 | C2: - | D2: - | E2: - | F2: - | G2: - | H2: - | K2: Historical Simulation VaR
A3: 44410 | B3: 141.983 | C3: =LN(B3/B2) -> -0.0022934176 | D3: - | E3: - | F3: - | G3: - | H3: - | K3: Confidence level | L3: 0.95 | M3: 0.99
A4: 44411 | B4: 143.77 | C4: =LN(B4/B3) -> 0.012507468 | D4: - | E4: - | F4: - | G4: - | H4: - | K4: Return percentile | L4: =_xlfn.PERCENTILE.INC(C3:C1256,1-L3) -> -0.02755893 | M4: =_xlfn.PERCENTILE.INC(C3:C1256,1-M3) -> -0.048560135
A5: 44412 | B5: 143.375 | C5: =LN(B5/B4) -> -0.002751225 | D5: - | E5: - | F5: - | G5: - | H5: - | K5: VaR(% of position) | L5: =-L4 -> 0.02755893 | M5: =-M4 -> 0.048560135
A6: 44413 | B6: 143.485 | C6: =LN(B6/B5) -> 0.00076692467 | D6: - | E6: - | F6: - | G6: - | H6: - | K6: Assumed position size($) | L6: 1000000 | M6: 1000000
A7: 44414 | B7: 142.797 | C7: =LN(B7/B6) -> -0.0048064588 | D7: - | E7: - | F7: - | G7: - | H7: - | K7: VaR($) | L7: =L5*L6 -> 27558.93 | M7: =M5*M6 -> 48560.135
A8: 44417 | B8: 142.747 | C8: =LN(B8/B7) -> -0.00035020873 | D8: - | E8: - | F8: - | G8: - | H8: -
A9: 44418 | B9: 142.28 | C9: =LN(B9/B8) -> -0.0032768855 | D9: - | E9: - | F9: - | G9: - | H9: -
A10: 44419 | B10: 142.523 | C10: =LN(B10/B9) -> 0.0017064431 | D10: - | E10: - | F10: - | G10: - | H10: - | K10: Parametric VaR
A11: 44420 | B11: 145.477 | C11: =LN(B11/B10) -> 0.020514608 | D11: - | E11: - | F11: - | G11: - | H11: - | K11: Confidence level | L11: 0.95 | M11: 0.99
A12: 44421 | B12: 145.681 | C12: =LN(B12/B11) -> 0.0014013012 | D12: - | E12: - | F12: - | G12: - | H12: - | K12: Mean daily return | L12: =AVERAGE(C3:C1256) -> 0.00067568973 | M12: =L12 -> 0.00067568973
A13: 44424 | B13: 147.664 | C13: =LN(B13/B12) -> 0.013520123 | D13: - | E13: - | F13: - | G13: - | H13: - | K13: Std. Dev. of daily return | L13: =_xlfn.STDEV.S(C3:C1256) -> 0.017475989 | M13: =L13 -> 0.017475989
A14: 44425 | B14: 146.754 | C14: =LN(B14/B13) -> -0.0061817069 | D14: - | E14: - | F14: - | G14: - | H14: - | K14: Z-score | L14: =_xlfn.NORM.S.INV(L11) -> 1.6448536 | M14: =_xlfn.NORM.S.INV(M11) -> 2.3263479
A15: 44426 | B15: 143.014 | C15: =LN(B15/B14) -> -0.025815188 | D15: - | E15: - | F15: - | G15: - | H15: - | K15: Parametric VaR(% of position) | L15: =L14*L13-L12 -> 0.028069753 | M15: =M14*M13-M12 -> 0.039979539
A16: 44427 | B16: 143.345 | C16: =LN(B16/B15) -> 0.0023117845 | D16: - | E16: - | F16: - | G16: - | H16: - | K16: Assumed position size($) | L16: 1000000 | M16: 1000000
A17: 44428 | B17: 144.79 | C17: =LN(B17/B16) -> 0.010030105 | D17: - | E17: - | F17: - | G17: - | H17: - | K17: Parametric VaR($) | L17: =L15*L16 -> 28069.753 | M17: =M15*M16 -> 39979.539
A18: 44431 | B18: 146.28 | C18: =LN(B18/B17) -> 0.010238176 | D18: - | E18: - | F18: - | G18: - | H18: -
A19: 44432 | B19: 146.193 | C19: =LN(B19/B18) -> -0.00059492673 | D19: - | E19: - | F19: - | G19: - | H19: -
A20: 44433 | B20: 144.955 | C20: =LN(B20/B19) -> -0.0085043171 | D20: - | E20: - | F20: - | G20: - | H20: -
A21: 44434 | B21: 144.151 | C21: =LN(B21/B20) -> -0.0055619881 | D21: - | E21: - | F21: - | G21: - | H21: -
A22: 44435 | B22: 145.193 | C22: =LN(B22/B21) -> 0.0072025306 | D22: - | E22: - | F22: - | G22: - | H22: -
A23: 44438 | B23: 149.626 | C23: =LN(B23/B22) -> 0.030074955 | D23: - | E23: - | F23: - | G23: - | H23: -
A24: 44439 | B24: 148.36 | C24: =LN(B24/B23) -> -0.0084970946 | D24: - | E24: - | F24: - | G24: - | H24: -
A25: 44440 | B25: 149.027 | C25: =LN(B25/B24) -> 0.004485745 | D25: - | E25: - | F25: - | G25: - | H25: -
A26: 44441 | B26: 150.138 | C26: =LN(B26/B25) -> 0.0074273736 | D26: - | E26: - | F26: - | G26: - | H26: -
A27: 44442 | B27: 150.766 | C27: =LN(B27/B26) -> 0.0041740948 | D27: - | E27: - | F27: - | G27: - | H27: -
A28: 44446 | B28: 153.102 | C28: =LN(B28/B27) -> 0.0153754 | D28: - | E28: - | F28: - | G28: - | H28: -
A29: 44447 | B29: 151.551 | C29: =LN(B29/B28) -> -0.010182164 | D29: - | E29: - | F29: - | G29: - | H29: -
... A251: 44769 | B251: 153.848 | C251: =LN(B251/B250) -> 0.033664445 | D251: - | E251: - | F251: - | G251: - | H251: -
A252: 44770 | B252: 154.396 | C252: =LN(B252/B251) -> 0.0035556285 | D252: =_xlfn.STDEV.S(C3:C252) -> 0.019009135 | E252: =_xlfn.NORM.S.INV(0.95)*D252 -> 0.031267244 | F252: =_xlfn.NORM.S.INV(0.99)*D252 -> 0.04422186 | G252: =-E252 -> -0.031267244 | H252: =-F252 -> -0.04422186
A253: 44771 | B253: 159.46 | C253: =LN(B253/B252) -> 0.032272377 | D253: =_xlfn.STDEV.S(C4:C253) -> 0.019115416 | E253: =_xlfn.NORM.S.INV(0.95)*D253 -> 0.031442061 | F253: =_xlfn.NORM.S.INV(0.99)*D253 -> 0.044469106 | G253: =-E253 -> -0.031442061 | H253: =-F253 -> -0.044469106
A254: 44774 | B254: 158.478 | C254: =LN(B254/B253) -> -0.0061773247 | D254: =_xlfn.STDEV.S(C5:C254) -> 0.019104664 | E254: =_xlfn.NORM.S.INV(0.95)*D254 -> 0.031424376 | F254: =_xlfn.NORM.S.INV(0.99)*D254 -> 0.044444094 | G254: =-E254 -> -0.031424376 | H254: =-F254 -> -0.044444094
A255: 44775 | B255: 157.005 | C255: =LN(B255/B254) -> -0.0093381304 | D255: =_xlfn.STDEV.S(C6:C255) -> 0.019113553 | E255: =_xlfn.NORM.S.INV(0.95)*D255 -> 0.031438997 | F255: =_xlfn.NORM.S.INV(0.99)*D255 -> 0.044464773 | G255: =-E255 -> -0.031438997 | H255: =-F255 -> -0.044464773
A256: 44776 | B256: 163.012 | C256: =LN(B256/B255) -> 0.037546166 | D256: =_xlfn.STDEV.S(C7:C256) -> 0.019257674 | E256: =_xlfn.NORM.S.INV(0.95)*D256 -> 0.031676055 | F256: =_xlfn.NORM.S.INV(0.99)*D256 -> 0.044800049 | G256: =-E256 -> -0.031676055 | H256: =-F256 -> -0.044800049
A257: 44777 | B257: 162.697 | C257: =LN(B257/B256) -> -0.0019342425 | D257: =_xlfn.STDEV.S(C8:C257) -> 0.019255346 | E257: =_xlfn.NORM.S.INV(0.95)*D257 -> 0.031672225 | F257: =_xlfn.NORM.S.INV(0.99)*D257 -> 0.044794633 | G257: =-E257 -> -0.031672225 | H257: =-F257 -> -0.044794633
A258: 44778 | B258: 162.47 | C258: =LN(B258/B257) -> -0.0013962059 | D258: =_xlfn.STDEV.S(C9:C258) -> 0.01925565 | E258: =_xlfn.NORM.S.INV(0.95)*D258 -> 0.031672725 | F258: =_xlfn.NORM.S.INV(0.99)*D258 -> 0.04479534 | G258: =-E258 -> -0.031672725 | H258: =-F258 -> -0.04479534
A259: 44781 | B259: 161.999 | C259: =LN(B259/B258) -> -0.002903207 | D259: =_xlfn.STDEV.S(C10:C259) -> 0.019255368 | E259: =_xlfn.NORM.S.INV(0.95)*D259 -> 0.031672263 | F259: =_xlfn.NORM.S.INV(0.99)*D259 -> 0.044794685 | G259: =-E259 -> -0.031672263 | H259: =-F259 -> -0.044794685
A260: 44782 | B260: 162.049 | C260: =LN(B260/B259) -> 0.00030859626 | D260: =_xlfn.STDEV.S(C11:C260) -> 0.019255225 | E260: =_xlfn.NORM.S.INV(0.95)*D260 -> 0.031672027 | F260: =_xlfn.NORM.S.INV(0.99)*D260 -> 0.044794352 | G260: =-E260 -> -0.031672027 | H260: =-F260 -> -0.044794352
A261: 44783 | B261: 166.293 | C261: =LN(B261/B260) -> 0.025852534 | D261: =_xlfn.STDEV.S(C12:C261) -> 0.019280436 | E261: =_xlfn.NORM.S.INV(0.95)*D261 -> 0.031713495 | F261: =_xlfn.NORM.S.INV(0.99)*D261 -> 0.044853001 | G261: =-E261 -> -0.031713495 | H261: =-F261 -> -0.044853001
...

Sheet Historical and Parametric VaR
B3: Historical Simulation VaR
B4: Confidence level | C4: 0.95 | D4: 0.99
B5: Return percentile | C5: -0.02755893 | D5: -0.048560135
B6: VaR(% of position) | C6: 0.02755893 | D6: 0.048560135
B7: Assumed position size($) | C7: 1000000 | D7: 1000000
B8: VaR($) | C8: 27558.93 | D8: 48560.135
B11: Parametric VaR
B12: Confidence level | C12: 0.95 | D12: 0.99
B13: Mean daily return | C13: 0.00067568973 | D13: 0.00067568973
B14: Std. Dev. of daily return | C14: 0.017475989 | D14: 0.017475989
B15: Z-score | C15: 1.6448536 | D15: 2.3263479
B16: Parametric VaR(% of position) | C16: 0.028069753 | D16: 0.039979539
B17: Assumed position size($) | C17: 1000000 | D17: 1000000
B18: Parametric VaR($) | C18: 28069.753 | D18: 39979.539
B21: Backtest & Kupiec test
C22: Historical 95% | D22: Historical 99% | E22: Parametric 95% | F22: Parametric 99%
B23: Confidence level | C23: 0.95 | D23: 0.99 | E23: 0.95 | F23: 0.99
B24: VaR(% of position) | C24: =Data!L5 -> 0.02755893 | D24: =Data!M5 -> 0.048560135 | E24: =Data!L15 -> 0.028069753 | F24: =Data!M15 -> 0.039979539
B25: Observations | C25: =COUNT(Data!C3:C1256) -> 1254 | D25: =C25 -> 1254 | E25: =C25 -> 1254 | F25: =C25 -> 1254
B26: Actual breaches | C26: =COUNTIF(Data!$C$3:$C$1256,"<" &-C$24) -> 63 | D26: =COUNTIF(Data!$C$3:$C$1256,"<" &-D$24) -> 13 | E26: =COUNTIF(Data!$C$3:$C$1256,"<" &-E$24) -> 62 | F26: =COUNTIF(Data!$C$3:$C$1256,"<" &-F$24) -> 20
B27: Expected breaches | C27: =(1-C$23)*C$25 -> 62.7 | D27: =(1-D$23)*D$25 -> 12.54 | E27: =(1-E$23)*E$25 -> 62.7 | F27: =(1-F$23)*F$25 -> 12.54
B28: Violation ratio | C28: =C$26/C$27 -> 1.0047847 | D28: =D$26/D$27 -> 1.0366826 | E28: =E$26/E$27 -> 0.98883573 | F28: =F$26/F$27 -> 1.5948963
B29: p(expected failure rate) | C29: =1-C$23 -> 0.05 | D29: =1-D$23 -> 0.01 | E29: =1-E$23 -> 0.05 | F29: =1-F$23 -> 0.01
B30: Kupiec LR statistic | C30: =-2*((C$25-C$26)*LN(1-C$29)+C$26*LN(C$29)-(C$25-C$26)*LN(1-(C$26/C$25))-C$26*LN(C$26/C$25)) -> 0.0015086769 | D30: =-2*((D$25-D$26)*LN(1-D$29)+D$26*LN(D$29)-(D$25-D$26)*LN(1-(D$26/D$25))-D$26*LN(D$26/D$25)) -> 0.016841844 | E30: =-2*((E$25-E$26)*LN(1-E$29)+E$26*LN(E$29)-(E$25-E$26)*LN(1-(E$26/E$25))-E$26*LN(E$26/E$25)) -> 0.0082554732 | F30: =-2*((F$25-F$26)*LN(1-F$29)+F$26*LN(F$29)-(F$25-F$26)*LN(1-(F$26/F$25))-F$26*LN(F$26/F$25)) -> 3.7972671
B31: Chi-square critical value | C31: =_xlfn.CHISQ.INV(0.95,1) -> 3.8414588 | D31: =_xlfn.CHISQ.INV(0.95,1) -> 3.8414588 | E31: =_xlfn.CHISQ.INV(0.95,1) -> 3.8414588 | F31: =_xlfn.CHISQ.INV(0.95,1) -> 3.8414588
B32: p-value | C32: =_xlfn.CHISQ.DIST.RT(C$30,1) -> 0.96901661 | D32: =_xlfn.CHISQ.DIST.RT(D$30,1) -> 0.89674355 | E32: =_xlfn.CHISQ.DIST.RT(E$30,1) -> 0.92760412 | F32: =_xlfn.CHISQ.DIST.RT(F$30,1) -> 0.051336307
B33: Kupiec result | C33: =IF(C$30>C$31,"Reject","Fail to reject") -> Fail to reject | D33: =IF(D$30>D$31,"Reject","Fail to reject") -> Fail to reject | E33: =IF(E$30>E$31,"Reject","Fail to reject") -> Fail to reject | F33: =IF(F$30>F$31,"Reject","Fail to reject") -> Fail to reject
B36: Stress test
B37: Volatility shock | C37: 0 | D37: 0.1 | E37: 0.2 | F37: 0.3
B38: Shocked Std. Dev. | C38: =C14 -> 0.017475989 | D38: =$C$14*(1+D$37) -> 0.019223587 | E38: =$C$14*(1+E$37) -> 0.020971186 | F38: =$C$14*(1+F$37) -> 0.022718785
B39: Shocked VaR % (99%) | C39: =_xlfn.NORM.S.INV(0.99)*C$38-$C$13 -> 0.039979539 | D39: =_xlfn.NORM.S.INV(0.99)*D$38-$C$13 -> 0.044045062 | E39: =_xlfn.NORM.S.INV(0.99)*E$38-$C$13 -> 0.048110585 | F39: =_xlfn.NORM.S.INV(0.99)*F$38-$C$13 -> 0.052176108
B40: Shocked VaR $ (99%) | C40: =C$39*$C$17 -> 39979.539 | D40: =D$39*$C$17 -> 44045.062 | E40: =E$39*$C$17 -> 48110.585 | F40: =F$39*$C$17 -> 52176.108
B41: % change vs baseline | C41: =(C$40-$C$40)/$C$40 -> 0 | D41: =(D$40-$C$40)/$C$40 -> 0.10169009 | E41: =(E$40-$C$40)/$C$40 -> 0.20338018 | F41: =(F$40-$C$40)/$C$40 -> 0.30507027

Sheet Chart
A1: Date | B1: Return | C1: Neg. VaR(95%) | D1: Neg. VaR(99%)
A2: 44770 | B2: 0.0035556285 | C2: -0.031267244 | D2: -0.04422186
A3: 44771 | B3: 0.032272377 | C3: -0.031442061 | D3: -0.044469106
A4: 44774 | B4: -0.0061773247 | C4: -0.031424376 | D4: -0.044444094
A5: 44775 | B5: -0.0093381304 | C5: -0.031438997 | D5: -0.044464773
A6: 44776 | B6: 0.037546166 | C6: -0.031676055 | D6: -0.044800049
A7: 44777 | B7: -0.0019342425 | C7: -0.031672225 | D7: -0.044794633
A8: 44778 | B8: -0.0013962059 | C8: -0.031672725 | D8: -0.04479534
A9: 44781 | B9: -0.002903207 | C9: -0.031672263 | D9: -0.044794685
A10: 44782 | B10: 0.00030859626 | C10: -0.031672027 | D10: -0.044794352
A11: 44783 | B11: 0.025852534 | C11: -0.031713495 | D11: -0.044853001
A12: 44784 | B12: -0.0044357463 | C12: -0.031717576 | D12: -0.044858772
A13: 44785 | B13: 0.021198364 | C13: -0.03176182 | D13: -0.044921348
... A1006: 46233 | B1006: -0.018292192 | C1006: -0.025733603 | D1006: -0.036395526
